Workbook

Sheet Data
A1: Colombia: historical indicators, 1980 to 2025
A2: Blue figures are source data (World Bank, World Development Indicators). Empty cells: not available for that year.
A4: Year | B4: Inflation | C4: Interest rate | D4: Unemployment | E4: GDP growth | F4: Public debt | G4: Fiscal balance | H4: Population | I4: Real GDP | J4: Real GDP per person | K4: GDP, current prices
B5: Consumer prices, annual % change | C5: Lending interest rate, % | D5: % of the labour force, national estimate | E5: Real GDP, annual % change | F5: Central government debt, % of GDP | G5: Central government net lending (+) / borrowing (-), % of GDP | H5: People | I5: Constant 2015 US$ | J5: Constant 2015 US$ | K5: Current US$
B6: FP.CPI.TOTL.ZG | C6: FR.INR.LEND | D6: SL.UEM.TOTL.NE.ZS | E6: NY.GDP.MKTP.KD.ZG | F6: GC.DOD.TOTL.GD.ZS | G6: GC.NLD.TOTL.GD.ZS | H6: SP.POP.TOTL | I6: NY.GDP.MKTP.KD | J6: NY.GDP.PCAP.KD | K6: NY.GDP.MKTP.CD
A7: 1980 | B7: 26.552653 | D7: 3.831 | E7: 4.0873537 | H7: 26104498 | I7: 8.6158201e+10 | J7: 3300.5117 | K7: 3.3400736e+10
A8: 1981 | B8: 27.453762 | D8: 8.135 | E8: 2.2768727 | H8: 26713267 | I8: 8.8119914e+10 | J8: 3298.7322 | K8: 3.6388367e+10
A9: 1982 | B9: 24.720988 | D9: 9.1 | E9: 0.94842079 | H9: 27338331 | I9: 8.8955661e+10 | J9: 3253.8805 | K9: 3.896804e+10
A10: 1983 | B10: 19.597317 | D10: 11.133 | E10: 1.573956 | H10: 27988173 | I10: 9.0355784e+10 | J10: 3228.3559 | K10: 3.8729823e+10
A11: 1984 | B11: 16.161617 | D11: 13.003 | E11: 3.3506837 | H11: 28642690 | I11: 9.3383321e+10 | J11: 3260.2846 | K11: 3.8253121e+10
A12: 1985 | B12: 24.090174 | D12: 13.887 | E12: 3.1071062 | H12: 29268470 | I12: 9.628484e+10 | J12: 3289.7121 | K12: 3.4894411e+10
A13: 1986 | B13: 18.842463 | C13: 40.220137 | D13: 13.043 | E13: 5.8240761 | H13: 29879112 | I13: 1.0189254e+11 | J13: 3410.1597 | K13: 3.494249e+10
A14: 1987 | B14: 23.302028 | C14: 40.48444 | D14: 10.927 | E14: 5.3689321 | H14: 30499467 | I14: 1.0736308e+11 | J14: 3520.1626 | K14: 3.6373307e+10
A15: 1988 | B15: 28.108397 | C15: 42.045638 | D15: 10.139 | E15: 4.0641732 | H15: 31130524 | I15: 1.1172651e+11 | J15: 3588.9696 | K15: 3.921255e+10
A16: 1989 | B16: 25.867548 | C16: 42.392024 | D16: 8.822 | E16: 3.4140961 | H16: 31776279 | I16: 1.1554096e+11 | J16: 3636.0757 | K16: 3.954008e+10
A17: 1990 | B17: 29.152025 | C17: 44.569657 | D17: 10.152 | E17: 4.2819983 | H17: 32440069 | I17: 1.2048842e+11 | J17: 3714.185 | K17: 4.7844091e+10
A18: 1991 | B18: 30.38782 | C18: 46.420604 | D18: 10.124 | E18: 2.0016076 | H18: 33098372 | I18: 1.2290012e+11 | J18: 3713.1773 | K18: 4.9175566e+10
A19: 1992 | B19: 27.010627 | C19: 36.719343 | D19: 9.435 | E19: 4.0449294 | H19: 33760571 | I19: 1.2787135e+11 | J19: 3787.5943 | K19: 5.8418985e+10
A20: 1993 | B20: 22.442483 | C20: 35.276343 | D20: 7.8 | E20: 5.3854099 | H20: 34441473 | I20: 1.3475774e+11 | J20: 3912.6591 | K20: 6.6446805e+10
A21: 1994 | B21: 22.846242 | C21: 39.857334 | D21: 7.6 | E21: 5.8146619 | H21: 35127410 | I21: 1.4259345e+11 | J21: 4059.3215 | K21: 8.1703501e+10
A22: 1995 | B22: 20.891793 | C22: 42.076009 | D22: 8.72 | E22: 5.2024376 | H22: 35804662 | I22: 1.5001178e+11 | J22: 4189.7277 | K22: 9.2507279e+10
A23: 1996 | B23: 20.797576 | C23: 41.361896 | D23: 11.806 | E23: 2.0558547 | H23: 36462745 | I23: 1.5309581e+11 | J23: 4198.6913 | K23: 9.7160109e+10
A24: 1997 | B24: 18.470022 | C24: 33.71022 | D24: 12.14 | E24: 3.4302937 | H24: 37121149 | I24: 1.5834744e+11 | J24: 4265.6935 | K24: 1.0665951e+11
A25: 1998 | B25: 18.67698 | C25: 41.604858 | D25: 15 | E25: 0.56978409 | F25: 5.4039155 | G25: -3.3846862 | H25: 37792165 | I25: 1.5924968e+11 | J25: 4213.828 | K25: 9.844374e+10
A26: 1999 | B26: 10.873687 | C26: 29.4258 | D26: 20.06 | E26: -4.2040152 | F26: 19.065351 | G26: -6.1130721 | H26: 38454863 | I26: 1.525548e+11 | J26: 3967.1134 | K26: 8.6186159e+10
A27: 2000 | B27: 9.2253482 | C27: 18.786667 | D27: 20.523 | E27: 2.9248615 | F27: 17.709022 | G27: -3.1222952 | H27: 39089934 | I27: 1.5701682e+11 | J27: 4016.8095 | K27: 9.9875075e+10
A28: 2001 | B28: 7.9655609 | C28: 20.72 | D28: 15.04 | E28: 1.6778983 | H28: 39709262 | I28: 1.596514e+11 | J28: 4020.5079 | K28: 9.8200641e+10
A29: 2002 | B29: 6.3515073 | C29: 16.326798 | D29: 14.481 | E29: 2.5039805 | H29: 40324680 | I29: 1.6364904e+11 | J29: 4058.2849 | K29: 9.7945813e+10
A30: 2003 | B30: 7.1297886 | C30: 15.187101 | D30: 13.221 | E30: 3.9182719 | F30: 52.53542 | G30: -5.0496701 | H30: 40937429 | I30: 1.7006126e+11 | J30: 4154.1753 | K30: 9.4644969e+10
A31: 2004 | B31: 5.9040201 | C31: 15.083057 | D31: 13.717 | E31: 5.3330221 | H31: 41543171 | I31: 1.7913066e+11 | J31: 4311.9159 | K31: 1.1709242e+11
A32: 2005 | B32: 5.0510196 | C32: 14.560833 | D32: 11.062 | E32: 4.8287611 | H32: 42128977 | I32: 1.8778045e+11 | J32: 4457.2754 | K32: 1.4560053e+11
A33: 2006 | B33: 4.2934236 | C33: 12.893913 | E33: 6.7168687 | H33: 42691084 | I33: 2.0039342e+11 | J33: 4694.0344 | K33: 1.6179296e+11
A34: 2007 | B34: 5.5443849 | C34: 15.38185 | D34: 10.252 | E34: 6.7381947 | H34: 43235374 | I34: 2.1389632e+11 | J34: 4947.2526 | K34: 2.0622954e+11
A35: 2008 | B35: 6.996885 | C35: 17.175623 | D35: 10.52 | E35: 3.2834462 | F35: 65.24508 | G35: -5.724508 | H35: 43758808 | I35: 2.2091949e+11 | J35: 5048.5719 | K35: 2.4250415e+11
A36: 2009 | B36: 4.2025166 | C36: 13.008075 | D36: 11.319 | E36: 1.1396486 | F36: 68.999003 | G36: -7.0818388 | H36: 44271541 | I36: 2.2343719e+11 | J36: 5046.9712 | K36: 2.3246866e+11
A37: 2010 | B37: 2.2720023 | C37: 9.3814899 | D37: 11.153 | E37: 4.494659 | F37: 72.45267 | G37: -4.5601182 | H37: 44777319 | I37: 2.3347993e+11 | J37: 5214.2455 | K37: 2.8649853e+11
A38: 2011 | B38: 3.4150334 | C38: 11.219918 | D38: 10.288 | E38: 6.947892 | F38: 62.860133 | G38: -1.0707562 | H38: 45259614 | I38: 2.4970187e+11 | J38: 5517.1011 | K38: 3.3496613e+11
A39: 2012 | B39: 3.1693019 | C39: 12.58504 | D39: 9.959 | E39: 3.9126358 | F39: 65.227696 | G39: 2.7655929 | H39: 45715810 | I39: 2.5947179e+11 | J39: 5675.7562 | K39: 3.7069114e+11
A40: 2013 | B40: 2.0169922 | C40: 10.985586 | D40: 9.246 | E40: 5.1339935 | F40: 67.102912 | G40: -5.5346956 | H40: 46151584 | I40: 2.7279306e+11 | J40: 5910.8059 | K40: 3.820937e+11
A41: 2014 | B41: 2.8988379 | C41: 10.867335 | D41: 8.799 | E41: 4.49903 | F41: 47.97617 | G41: -4.1668122 | H41: 46565429 | I41: 2.850661e+11 | J41: 6121.8398 | K41: 3.8124086e+11
...

Sheet Decades
A1: Averages by decade
A2: Percent. Averages of the years available in each decade (formulas on the Data sheet).
A4: Indicator | B4: 1980s | C4: 1990s | D4: 2000s | E4: 2010s | F4: 2020 to 2025
A5: Inflation: Consumer prices, annual % change | B5: =IFERROR(AVERAGEIFS(Data!$B$7:$B$52,Data!$A$7:$A$52,">=1980",Data!$A$7:$A$52,"<=1989"),"n/a") -> 23.469695 | C5: =IFERROR(AVERAGEIFS(Data!$B$7:$B$52,Data!$A$7:$A$52,">=1990",Data!$A$7:$A$52,"<=1999"),"n/a") -> 22.154925 | D5: =IFERROR(AVERAGEIFS(Data!$B$7:$B$52,Data!$A$7:$A$52,">=2000",Data!$A$7:$A$52,"<=2009"),"n/a") -> 6.2664455 | E5: =IFERROR(AVERAGEIFS(Data!$B$7:$B$52,Data!$A$7:$A$52,">=2010",Data!$A$7:$A$52,"<=2019"),"n/a") -> 3.7353361 | F5: =IFERROR(AVERAGEIFS(Data!$B$7:$B$52,Data!$A$7:$A$52,">=2020",Data!$A$7:$A$52,"<=2025"),"n/a") -> 6.6143572
A6: Interest rate: Lending interest rate, % | B6: =IFERROR(AVERAGEIFS(Data!$C$7:$C$52,Data!$A$7:$A$52,">=1980",Data!$A$7:$A$52,"<=1989"),"n/a") -> 41.28556 | C6: =IFERROR(AVERAGEIFS(Data!$C$7:$C$52,Data!$A$7:$A$52,">=1990",Data!$A$7:$A$52,"<=1999"),"n/a") -> 39.102206 | D6: =IFERROR(AVERAGEIFS(Data!$C$7:$C$52,Data!$A$7:$A$52,">=2000",Data!$A$7:$A$52,"<=2009"),"n/a") -> 15.912392 | E6: =IFERROR(AVERAGEIFS(Data!$C$7:$C$52,Data!$A$7:$A$52,">=2010",Data!$A$7:$A$52,"<=2019"),"n/a") -> 11.870456 | F6: =IFERROR(AVERAGEIFS(Data!$C$7:$C$52,Data!$A$7:$A$52,">=2020",Data!$A$7:$A$52,"<=2025"),"n/a") -> 14.452063
A7: Unemployment: % of the labour force, national estimate | B7: =IFERROR(AVERAGEIFS(Data!$D$7:$D$52,Data!$A$7:$A$52,">=1980",Data!$A$7:$A$52,"<=1989"),"n/a") -> 10.202 | C7: =IFERROR(AVERAGEIFS(Data!$D$7:$D$52,Data!$A$7:$A$52,">=1990",Data!$A$7:$A$52,"<=1999"),"n/a") -> 11.2837 | D7: =IFERROR(AVERAGEIFS(Data!$D$7:$D$52,Data!$A$7:$A$52,">=2000",Data!$A$7:$A$52,"<=2009"),"n/a") -> 13.348333 | E7: =IFERROR(AVERAGEIFS(Data!$D$7:$D$52,Data!$A$7:$A$52,">=2010",Data!$A$7:$A$52,"<=2019"),"n/a") -> 9.5665 | F7: =IFERROR(AVERAGEIFS(Data!$D$7:$D$52,Data!$A$7:$A$52,">=2020",Data!$A$7:$A$52,"<=2025"),"n/a") -> 11.274167
A8: GDP growth: Real GDP, annual % change | B8: =IFERROR(AVERAGEIFS(Data!$E$7:$E$52,Data!$A$7:$A$52,">=1980",Data!$A$7:$A$52,"<=1989"),"n/a") -> 3.4015671 | C8: =IFERROR(AVERAGEIFS(Data!$E$7:$E$52,Data!$A$7:$A$52,">=1990",Data!$A$7:$A$52,"<=1999"),"n/a") -> 2.8582962 | D8: =IFERROR(AVERAGEIFS(Data!$E$7:$E$52,Data!$A$7:$A$52,">=2000",Data!$A$7:$A$52,"<=2009"),"n/a") -> 3.9064954 | E8: =IFERROR(AVERAGEIFS(Data!$E$7:$E$52,Data!$A$7:$A$52,">=2010",Data!$A$7:$A$52,"<=2019"),"n/a") -> 3.7142035 | F8: =IFERROR(AVERAGEIFS(Data!$E$7:$E$52,Data!$A$7:$A$52,">=2020",Data!$A$7:$A$52,"<=2025"),"n/a") -> 2.6534506
A9: Public debt: Central government debt, % of GDP | B9: =IFERROR(AVERAGEIFS(Data!$F$7:$F$52,Data!$A$7:$A$52,">=1980",Data!$A$7:$A$52,"<=1989"),"n/a") -> n/a | C9: =IFERROR(AVERAGEIFS(Data!$F$7:$F$52,Data!$A$7:$A$52,">=1990",Data!$A$7:$A$52,"<=1999"),"n/a") -> 12.234633 | D9: =IFERROR(AVERAGEIFS(Data!$F$7:$F$52,Data!$A$7:$A$52,">=2000",Data!$A$7:$A$52,"<=2009"),"n/a") -> 51.122131 | E9: =IFERROR(AVERAGEIFS(Data!$F$7:$F$52,Data!$A$7:$A$52,">=2010",Data!$A$7:$A$52,"<=2019"),"n/a") -> 64.688703 | F9: =IFERROR(AVERAGEIFS(Data!$F$7:$F$52,Data!$A$7:$A$52,">=2020",Data!$A$7:$A$52,"<=2025"),"n/a") -> 76.850597
A10: Fiscal balance: Central government net lending (+) / borrowing (-), % of GDP | B10: =IFERROR(AVERAGEIFS(Data!$G$7:$G$52,Data!$A$7:$A$52,">=1980",Data!$A$7:$A$52,"<=1989"),"n/a") -> n/a | C10: =IFERROR(AVERAGEIFS(Data!$G$7:$G$52,Data!$A$7:$A$52,">=1990",Data!$A$7:$A$52,"<=1999"),"n/a") -> -4.7488792 | D10: =IFERROR(AVERAGEIFS(Data!$G$7:$G$52,Data!$A$7:$A$52,">=2000",Data!$A$7:$A$52,"<=2009"),"n/a") -> -5.244578 | E10: =IFERROR(AVERAGEIFS(Data!$G$7:$G$52,Data!$A$7:$A$52,">=2010",Data!$A$7:$A$52,"<=2019"),"n/a") -> -2.4066475 | F10: =IFERROR(AVERAGEIFS(Data!$G$7:$G$52,Data!$A$7:$A$52,">=2020",Data!$A$7:$A$52,"<=2025"),"n/a") -> -5.6284705

Sheet Index 1980=100
A1: Population and output, index 1980 = 100
A2: Each series divided by its 1980 value and multiplied by 100, so that series in different units can be compared.
A4: Year | B4: Population | C4: Real GDP | D4: Real GDP per person
A5: 1980 | B5: =Data!H7/Data!H$7*100 -> 100 | C5: =Data!I7/Data!I$7*100 -> 100 | D5: =Data!J7/Data!J$7*100 -> 100
A6: 1981 | B6: =Data!H8/Data!H$7*100 -> 102.33205 | C6: =Data!I8/Data!I$7*100 -> 102.27687 | D6: =Data!J8/Data!J$7*100 -> 99.946084
A7: 1982 | B7: =Data!H9/Data!H$7*100 -> 104.72651 | C7: =Data!I9/Data!I$7*100 -> 103.24689 | D7: =Data!J9/Data!J$7*100 -> 98.587151
A8: 1983 | B8: =Data!H10/Data!H$7*100 -> 107.2159 | C8: =Data!I10/Data!I$7*100 -> 104.87195 | D8: =Data!J10/Data!J$7*100 -> 97.8138
A9: 1984 | B9: =Data!H11/Data!H$7*100 -> 109.7232 | C9: =Data!I11/Data!I$7*100 -> 108.38588 | D9: =Data!J11/Data!J$7*100 -> 98.781186
A10: 1985 | B10: =Data!H12/Data!H$7*100 -> 112.12041 | C10: =Data!I12/Data!I$7*100 -> 111.75354 | D10: =Data!J12/Data!J$7*100 -> 99.67279
A11: 1986 | B11: =Data!H13/Data!H$7*100 -> 114.45963 | C11: =Data!I13/Data!I$7*100 -> 118.26215 | D11: =Data!J13/Data!J$7*100 -> 103.32215
A12: 1987 | B12: =Data!H14/Data!H$7*100 -> 116.83606 | C12: =Data!I14/Data!I$7*100 -> 124.61157 | D12: =Data!J14/Data!J$7*100 -> 106.65506
A13: 1988 | B13: =Data!H15/Data!H$7*100 -> 119.25349 | C13: =Data!I15/Data!I$7*100 -> 129.676 | D13: =Data!J15/Data!J$7*100 -> 108.73979
A14: 1989 | B14: =Data!H16/Data!H$7*100 -> 121.72722 | C14: =Data!I16/Data!I$7*100 -> 134.10326 | D14: =Data!J16/Data!J$7*100 -> 110.16703
A15: 1990 | B15: =Data!H17/Data!H$7*100 -> 124.27004 | C15: =Data!I17/Data!I$7*100 -> 139.84556 | D15: =Data!J17/Data!J$7*100 -> 112.53361
A16: 1991 | B16: =Data!H18/Data!H$7*100 -> 126.79183 | C16: =Data!I18/Data!I$7*100 -> 142.64472 | D16: =Data!J18/Data!J$7*100 -> 112.50308
... A50: 2025 | B50: =Data!H52/Data!H$7*100 -> 204.66065 | C50: =Data!I52/Data!I$7*100 -> 432.54628 | D50: =Data!J52/Data!J$7*100 -> 211.34805

Sheet Normalized
A1: Normalized indicators: standard deviations from each indicator's own average
A2: z = (value - average of the series) / standard deviation of the series. 0 is a normal year for that indicator.
A4: Year | B4: Inflation | C4: Interest rate | D4: Unemployment | E4: GDP growth | F4: Public debt | G4: Fiscal balance
A5: 1980 | B5: =IF(Data!B7="","",(Data!B7-AVERAGE(Data!B$7:B$52))/_xlfn.STDEV.P(Data!B$7:B$52)) -> 1.4498775 | C5: =IF(Data!C7="","",(Data!C7-AVERAGE(Data!C$7:C$52))/_xlfn.STDEV.P(Data!C$7:C$52)) | D5: =IF(Data!D7="","",(Data!D7-AVERAGE(Data!D$7:D$52))/_xlfn.STDEV.P(Data!D$7:D$52)) -> -2.385133 | E5: =IF(Data!E7="","",(Data!E7-AVERAGE(Data!E$7:E$52))/_xlfn.STDEV.P(Data!E$7:E$52)) -> 0.25851564 | F5: =IF(Data!F7="","",(Data!F7-AVERAGE(Data!F$7:F$52))/_xlfn.STDEV.P(Data!F$7:F$52)) | G5: =IF(Data!G7="","",(Data!G7-AVERAGE(Data!G$7:G$52))/_xlfn.STDEV.P(Data!G$7:G$52))
A6: 1981 | B6: =IF(Data!B8="","",(Data!B8-AVERAGE(Data!B$7:B$52))/_xlfn.STDEV.P(Data!B$7:B$52)) -> 1.5459632 | C6: =IF(Data!C8="","",(Data!C8-AVERAGE(Data!C$7:C$52))/_xlfn.STDEV.P(Data!C$7:C$52)) | D6: =IF(Data!D8="","",(Data!D8-AVERAGE(Data!D$7:D$52))/_xlfn.STDEV.P(Data!D$7:D$52)) -> -0.96769623 | E6: =IF(Data!E8="","",(Data!E8-AVERAGE(Data!E$7:E$52))/_xlfn.STDEV.P(Data!E$7:E$52)) -> -0.38817928 | F6: =IF(Data!F8="","",(Data!F8-AVERAGE(Data!F$7:F$52))/_xlfn.STDEV.P(Data!F$7:F$52)) | G6: =IF(Data!G8="","",(Data!G8-AVERAGE(Data!G$7:G$52))/_xlfn.STDEV.P(Data!G$7:G$52))
A7: 1982 | B7: =IF(Data!B9="","",(Data!B9-AVERAGE(Data!B$7:B$52))/_xlfn.STDEV.P(Data!B$7:B$52)) -> 1.2545662 | C7: =IF(Data!C9="","",(Data!C9-AVERAGE(Data!C$7:C$52))/_xlfn.STDEV.P(Data!C$7:C$52)) | D7: =IF(Data!D9="","",(Data!D9-AVERAGE(Data!D$7:D$52))/_xlfn.STDEV.P(Data!D$7:D$52)) -> -0.64989269 | E7: =IF(Data!E9="","",(Data!E9-AVERAGE(Data!E$7:E$52))/_xlfn.STDEV.P(Data!E$7:E$52)) -> -0.8626958 | F7: =IF(Data!F9="","",(Data!F9-AVERAGE(Data!F$7:F$52))/_xlfn.STDEV.P(Data!F$7:F$52)) | G7: =IF(Data!G9="","",(Data!G9-AVERAGE(Data!G$7:G$52))/_xlfn.STDEV.P(Data!G$7:G$52))
A8: 1983 | B8: =IF(Data!B10="","",(Data!B10-AVERAGE(Data!B$7:B$52))/_xlfn.STDEV.P(Data!B$7:B$52)) -> 0.7082267 | C8: =IF(Data!C10="","",(Data!C10-AVERAGE(Data!C$7:C$52))/_xlfn.STDEV.P(Data!C$7:C$52)) | D8: =IF(Data!D10="","",(Data!D10-AVERAGE(Data!D$7:D$52))/_xlfn.STDEV.P(Data!D$7:D$52)) -> 0.019635392 | E8: =IF(Data!E10="","",(Data!E10-AVERAGE(Data!E$7:E$52))/_xlfn.STDEV.P(Data!E$7:E$52)) -> -0.63925768 | F8: =IF(Data!F10="","",(Data!F10-AVERAGE(Data!F$7:F$52))/_xlfn.STDEV.P(Data!F$7:F$52)) | G8: =IF(Data!G10="","",(Data!G10-AVERAGE(Data!G$7:G$52))/_xlfn.STDEV.P(Data!G$7:G$52))
A9: 1984 | B9: =IF(Data!B11="","",(Data!B11-AVERAGE(Data!B$7:B$52))/_xlfn.STDEV.P(Data!B$7:B$52)) -> 0.34187638 | C9: =IF(Data!C11="","",(Data!C11-AVERAGE(Data!C$7:C$52))/_xlfn.STDEV.P(Data!C$7:C$52)) | D9: =IF(Data!D11="","",(Data!D11-AVERAGE(Data!D$7:D$52))/_xlfn.STDEV.P(Data!D$7:D$52)) -> 0.63548267 | E9: =IF(Data!E11="","",(Data!E11-AVERAGE(Data!E$7:E$52))/_xlfn.STDEV.P(Data!E$7:E$52)) -> -0.0046192528 | F9: =IF(Data!F11="","",(Data!F11-AVERAGE(Data!F$7:F$52))/_xlfn.STDEV.P(Data!F$7:F$52)) | G9: =IF(Data!G11="","",(Data!G11-AVERAGE(Data!G$7:G$52))/_xlfn.STDEV.P(Data!G$7:G$52))
A10: 1985 | B10: =IF(Data!B12="","",(Data!B12-AVERAGE(Data!B$7:B$52))/_xlfn.STDEV.P(Data!B$7:B$52)) -> 1.1873022 | C10: =IF(Data!C12="","",(Data!C12-AVERAGE(Data!C$7:C$52))/_xlfn.STDEV.P(Data!C$7:C$52)) | D10: =IF(Data!D12="","",(Data!D12-AVERAGE(Data!D$7:D$52))/_xlfn.STDEV.P(Data!D$7:D$52)) -> 0.92661047 | E10: =IF(Data!E12="","",(Data!E12-AVERAGE(Data!E$7:E$52))/_xlfn.STDEV.P(Data!E$7:E$52)) -> -0.091623957 | F10: =IF(Data!F12="","",(Data!F12-AVERAGE(Data!F$7:F$52))/_xlfn.STDEV.P(Data!F$7:F$52)) | G10: =IF(Data!G12="","",(Data!G12-AVERAGE(Data!G$7:G$52))/_xlfn.STDEV.P(Data!G$7:G$52))
A11: 1986 | B11: =IF(Data!B13="","",(Data!B13-AVERAGE(Data!B$7:B$52))/_xlfn.STDEV.P(Data!B$7:B$52)) -> 0.62773627 | C11: =IF(Data!C13="","",(Data!C13-AVERAGE(Data!C$7:C$52))/_xlfn.STDEV.P(Data!C$7:C$52)) -> 1.3462873 | D11: =IF(Data!D13="","",(Data!D13-AVERAGE(Data!D$7:D$52))/_xlfn.STDEV.P(Data!D$7:D$52)) -> 0.64865587 | E11: =IF(Data!E13="","",(Data!E13-AVERAGE(Data!E$7:E$52))/_xlfn.STDEV.P(Data!E$7:E$52)) -> 0.87886439 | F11: =IF(Data!F13="","",(Data!F13-AVERAGE(Data!F$7:F$52))/_xlfn.STDEV.P(Data!F$7:F$52)) | G11: =IF(Data!G13="","",(Data!G13-AVERAGE(Data!G$7:G$52))/_xlfn.STDEV.P(Data!G$7:G$52))
A12: 1987 | B12: =IF(Data!B14="","",(Data!B14-AVERAGE(Data!B$7:B$52))/_xlfn.STDEV.P(Data!B$7:B$52)) -> 1.1032618 | C12: =IF(Data!C14="","",(Data!C14-AVERAGE(Data!C$7:C$52))/_xlfn.STDEV.P(Data!C$7:C$52)) -> 1.366972 | D12: =IF(Data!D14="","",(Data!D14-AVERAGE(Data!D$7:D$52))/_xlfn.STDEV.P(Data!D$7:D$52)) -> -0.048206607 | E12: =IF(Data!E14="","",(Data!E14-AVERAGE(Data!E$7:E$52))/_xlfn.STDEV.P(Data!E$7:E$52)) -> 0.71628919 | F12: =IF(Data!F14="","",(Data!F14-AVERAGE(Data!F$7:F$52))/_xlfn.STDEV.P(Data!F$7:F$52)) | G12: =IF(Data!G14="","",(Data!G14-AVERAGE(Data!G$7:G$52))/_xlfn.STDEV.P(Data!G$7:G$52))
A13: 1988 | B13: =IF(Data!B15="","",(Data!B15-AVERAGE(Data!B$7:B$52))/_xlfn.STDEV.P(Data!B$7:B$52)) -> 1.6157672 | C13: =IF(Data!C15="","",(Data!C15-AVERAGE(Data!C$7:C$52))/_xlfn.STDEV.P(Data!C$7:C$52)) -> 1.4891531 | D13: =IF(Data!D15="","",(Data!D15-AVERAGE(Data!D$7:D$52))/_xlfn.STDEV.P(Data!D$7:D$52)) -> -0.30771872 | E13: =IF(Data!E15="","",(Data!E15-AVERAGE(Data!E$7:E$52))/_xlfn.STDEV.P(Data!E$7:E$52)) -> 0.2502357 | F13: =IF(Data!F15="","",(Data!F15-AVERAGE(Data!F$7:F$52))/_xlfn.STDEV.P(Data!F$7:F$52)) | G13: =IF(Data!G15="","",(Data!G15-AVERAGE(Data!G$7:G$52))/_xlfn.STDEV.P(Data!G$7:G$52))
A14: 1989 | B14: =IF(Data!B16="","",(Data!B16-AVERAGE(Data!B$7:B$52))/_xlfn.STDEV.P(Data!B$7:B$52)) -> 1.3768244 | C14: =IF(Data!C16="","",(Data!C16-AVERAGE(Data!C$7:C$52))/_xlfn.STDEV.P(Data!C$7:C$52)) -> 1.5162617 | D14: =IF(Data!D16="","",(Data!D16-AVERAGE(Data!D$7:D$52))/_xlfn.STDEV.P(Data!D$7:D$52)) -> -0.74144646 | E14: =IF(Data!E16="","",(Data!E16-AVERAGE(Data!E$7:E$52))/_xlfn.STDEV.P(Data!E$7:E$52)) -> 0.018031335 | F14: =IF(Data!F16="","",(Data!F16-AVERAGE(Data!F$7:F$52))/_xlfn.STDEV.P(Data!F$7:F$52)) | G14: =IF(Data!G16="","",(Data!G16-AVERAGE(Data!G$7:G$52))/_xlfn.STDEV.P(Data!G$7:G$52))
A15: 1990 | B15: =IF(Data!B17="","",(Data!B17-AVERAGE(Data!B$7:B$52))/_xlfn.STDEV.P(Data!B$7:B$52)) -> 1.7270497 | C15: =IF(Data!C17="","",(Data!C17-AVERAGE(Data!C$7:C$52))/_xlfn.STDEV.P(Data!C$7:C$52)) -> 1.6866856 | D15: =IF(Data!D17="","",(Data!D17-AVERAGE(Data!D$7:D$52))/_xlfn.STDEV.P(Data!D$7:D$52)) -> -0.30343743 | E15: =IF(Data!E17="","",(Data!E17-AVERAGE(Data!E$7:E$52))/_xlfn.STDEV.P(Data!E$7:E$52)) -> 0.32804175 | F15: =IF(Data!F17="","",(Data!F17-AVERAGE(Data!F$7:F$52))/_xlfn.STDEV.P(Data!F$7:F$52)) | G15: =IF(Data!G17="","",(Data!G17-AVERAGE(Data!G$7:G$52))/_xlfn.STDEV.P(Data!G$7:G$52))
A16: 1991 | B16: =IF(Data!B18="","",(Data!B18-AVERAGE(Data!B$7:B$52))/_xlfn.STDEV.P(Data!B$7:B$52)) -> 1.8588232 | C16: =IF(Data!C18="","",(Data!C18-AVERAGE(Data!C$7:C$52))/_xlfn.STDEV.P(Data!C$7:C$52)) -> 1.8315428 | D16: =IF(Data!D18="","",(Data!D18-AVERAGE(Data!D$7:D$52))/_xlfn.STDEV.P(Data!D$7:D$52)) -> -0.31265867 | E16: =IF(Data!E18="","",(Data!E18-AVERAGE(Data!E$7:E$52))/_xlfn.STDEV.P(Data!E$7:E$52)) -> -0.48650264 | F16: =IF(Data!F18="","",(Data!F18-AVERAGE(Data!F$7:F$52))/_xlfn.STDEV.P(Data!F$7:F$52)) | G16: =IF(Data!G18="","",(Data!G18-AVERAGE(Data!G$7:G$52))/_xlfn.STDEV.P(Data!G$7:G$52))
... A50: 2025 | B50: =IF(Data!B52="","",(Data!B52-AVERAGE(Data!B$7:B$52))/_xlfn.STDEV.P(Data!B$7:B$52)) -> -0.83312622 | C50: =IF(Data!C52="","",(Data!C52-AVERAGE(Data!C$7:C$52))/_xlfn.STDEV.P(Data!C$7:C$52)) -> -0.68135611 | D50: =IF(Data!D52="","",(Data!D52-AVERAGE(Data!D$7:D$52))/_xlfn.STDEV.P(Data!D$7:D$52)) -> -0.87120251 | E50: =IF(Data!E52="","",(Data!E52-AVERAGE(Data!E$7:E$52))/_xlfn.STDEV.P(Data!E$7:E$52)) -> -0.25775208 | F50: =IF(Data!F52="","",(Data!F52-AVERAGE(Data!F$7:F$52))/_xlfn.STDEV.P(Data!F$7:F$52)) | G50: =IF(Data!G52="","",(Data!G52-AVERAGE(Data!G$7:G$52))/_xlfn.STDEV.P(Data!G$7:G$52))

Sheet Notes
A1: Notes
A2: Definitions
A3: Inflation: Consumer prices, annual % change. World Bank code FP.CPI.TOTL.ZG.
A4: Interest rate: Lending interest rate, %. World Bank code FR.INR.LEND.
A5: Unemployment: % of the labour force, national estimate. World Bank code SL.UEM.TOTL.NE.ZS.
A6: GDP growth: Real GDP, annual % change. World Bank code NY.GDP.MKTP.KD.ZG.
A7: Public debt: Central government debt, % of GDP. World Bank code GC.DOD.TOTL.GD.ZS.
A8: Fiscal balance: Central government net lending (+) / borrowing (-), % of GDP. World Bank code GC.NLD.TOTL.GD.ZS.
A9: Population: People. World Bank code SP.POP.TOTL.
A10: Real GDP: Constant 2015 US$. World Bank code NY.GDP.MKTP.KD.
A11: Real GDP per person: Constant 2015 US$. World Bank code NY.GDP.PCAP.KD.
A12: GDP, current prices: Current US$. World Bank code NY.GDP.MKTP.CD.
... A22: Retrieved on 2026-10-13.
