Workbook

Sheet LBO
A1: Leveraged buyout model: Dropbox
A2: Hypothetical transaction at 31 December 2025. USD millions, except per-share data. Blue figures are inputs; black figures are formulas.
A4: Transaction assumptions
A5: Share price, 31 Dec 2025 (USD) | B5: 27.799999 | C5: Yahoo Finance closing price
A6: Acquisition premium | B6: 0.3 | C6: Assumption
A7: Offer price per share (USD) | B7: =B5*(1+B6) -> 36.139999
A8: Diluted shares (millions) | B8: 272.8 | C8: Form 10-K, weighted average for 2025
A9: Equity purchase price | B9: =B7*B8 -> 9858.9917
A10: Existing debt, refinanced | B10: 2819 | C10: Form 10-K: convertible notes and credit facility; excludes leases
A11: Existing cash and short-term investments | B11: 1038.2 | C11: Form 10-K
A12: Enterprise value | B12: =B9+B10-B11 -> 11639.792
A13: EBITDA, 2025 | B13: =C44 -> 846.6
A14: Entry EV / EBITDA | B14: =B12/B13 -> 13.748868
A15: Transaction fees, % of enterprise value | B15: 0.02 | C15: Assumption
A16: Minimum cash kept in the company | B16: 200 | C16: Assumption
A17: Term loan, x EBITDA | B17: 4.5 | C17: Assumption
A18: Term loan interest rate | B18: 0.085 | C18: Assumption
A19: Senior notes, x EBITDA | B19: 1.5 | C19: Assumption
A20: Senior notes interest rate | B20: 0.105 | C20: Assumption
A21: Tax rate | B21: 0.21 | C21: US federal statutory rate
A22: Exit EV / EBITDA | B22: =B14 -> 13.748868 | C22: Set equal to the entry multiple
A24: Sources and uses
A25: Uses
A26: Purchase of equity | B26: =B9 -> 9858.9917
A27: Refinancing of existing debt | B27: =B10 -> 2819
A28: Transaction fees | B28: =B12*B15 -> 232.79583
A29: Total uses | B29: =SUM(B26:B28) -> 12910.788
A31: Sources
A32: Term loan | B32: =B17*B13 -> 3809.7
A33: Senior notes | B33: =B19*B13 -> 1269.9
A34: Cash from the company's balance sheet | B34: =B11-B16 -> 838.2
A35: Sponsor equity | B35: =B29-B32-B33-B34 -> 6992.9876
A36: Total sources | B36: =SUM(B32:B35) -> 12910.788
A37: Sponsor equity, % of total sources | B37: =B35/B36 -> 0.54163912
A38: Total debt / EBITDA at entry | B38: =(B32+B33)/B13 -> 6
B40: Historical | C40: Historical | D40: Projected | E40: Projected | F40: Projected | G40: Projected | H40: Projected
A41: Fiscal year ended 31 December | B41: 2024 | C41: 2025 | D41: 2026 | E41: 2027 | F41: 2028 | G41: 2029 | H41: 2030
A42: Revenue | B42: 2548.2 | C42: 2521 | D42: =C42*(1+D43) -> 2521 | E42: =D42*(1+E43) -> 2546.21 | F42: =E42*(1+F43) -> 2571.6721 | G42: =F42*(1+G43) -> 2623.1055 | H42: =G42*(1+H43) -> 2675.5677
A43: % growth | C43: =C42/B42-1 -> -0.010674201 | D43: 0 | E43: 0.01 | F43: 0.01 | G43: 0.02 | H43: 0.02
A44: EBITDA | B44: 623.3 | C44: 846.6 | D44: =D42*D45 -> 907.56 | E44: =E42*E45 -> 967.5598 | F44: =F42*F45 -> 1028.6688 | G44: =G42*G45 -> 1075.4733 | H44: =H42*H45 -> 1123.7384
...

Sheet Sensitivity
A1: Sensitivity: sponsor IRR to exit multiple and exit year
A2: Rows: exit EV / EBITDA. Columns: year of exit.
A4: Exit multiple \ Exit year | B4: 2028 | C4: 2029 | D4: 2030
A5: =LBO!$B$22+(-2) -> 11.748868 | B5: =((LBO!F44*$A5-LBO!F67)/LBO!$B$35)^(1/3)-1 -> 0.05047723 | C5: =((LBO!G44*$A5-LBO!G67)/LBO!$B$35)^(1/4)-1 -> 0.067493077 | D5: =((LBO!H44*$A5-LBO!H67)/LBO!$B$35)^(1/5)-1 -> 0.077074258
A6: =LBO!$B$22+(-1) -> 12.748868 | B6: =((LBO!F44*$A6-LBO!F67)/LBO!$B$35)^(1/3)-1 -> 0.093154236 | C6: =((LBO!G44*$A6-LBO!G67)/LBO!$B$35)^(1/4)-1 -> 0.097785936 | D6: =((LBO!H44*$A6-LBO!H67)/LBO!$B$35)^(1/5)-1 -> 0.099961538
A7: =LBO!$B$22+(0) -> 13.748868 | B7: =((LBO!F44*$A7-LBO!F67)/LBO!$B$35)^(1/3)-1 -> 0.13273628 | C7: =((LBO!G44*$A7-LBO!G67)/LBO!$B$35)^(1/4)-1 -> 0.12576026 | D7: =((LBO!H44*$A7-LBO!H67)/LBO!$B$35)^(1/5)-1 -> 0.12108866
A8: =LBO!$B$22+(1) -> 14.748868 | B8: =((LBO!F44*$A8-LBO!F67)/LBO!$B$35)^(1/3)-1 -> 0.16972997 | C8: =((LBO!G44*$A8-LBO!G67)/LBO!$B$35)^(1/4)-1 -> 0.15179211 | D8: =((LBO!H44*$A8-LBO!H67)/LBO!$B$35)^(1/5)-1 -> 0.1407337
A9: =LBO!$B$22+(2) -> 15.748868 | B9: =((LBO!F44*$A9-LBO!F67)/LBO!$B$35)^(1/3)-1 -> 0.20452099 | C9: =((LBO!G44*$A9-LBO!G67)/LBO!$B$35)^(1/4)-1 -> 0.17616975 | D9: =((LBO!H44*$A9-LBO!H67)/LBO!$B$35)^(1/5)-1 -> 0.15911187

Sheet Notes
A1: Notes
A2: Method
A3: A financial sponsor buys all the shares at a premium, refinances the existing debt and funds the purchase with new debt and its own equity.
A4: During the holding period, all free cash flow repays the term loan (cash sweep). Interest is calculated on the balance at the beginning of each year.
A5: At exit, the company is sold at an EV / EBITDA multiple. Exit equity value = exit enterprise value - net debt.
A6: MOIC = exit equity value / sponsor equity invested. IRR = MOIC ^ (1 / years) - 1, since there are no interim dividends.
A8: Assumptions
A9: This is a hypothetical transaction built for illustration. It does not describe any real or proposed deal.
A10: The premium, leverage, interest rates, fees, revenue growth, EBITDA margins and capital expenditures are the author's assumptions.
A11: EBITDA is operating income plus depreciation and amortization of intangible assets, after stock-based compensation expense.
A12: Capital expenditures of 6% of sales are meant to cover purchases of equipment and payments on finance leases, which Dropbox uses for its data-center equipment.
A13: Changes in net working capital are assumed to be zero. Lease liabilities are not treated as debt.
... A20: Retrieved on 2026-10-13.
