Workbook

Sheet DCF
A1: Discounted cash flow model: Amazon
A2: Valuation date 31 December 2025. USD millions, except per-share data. Blue figures are inputs; black figures are formulas.
A4: Assumptions
A5: Scenario switch (1 = Conservative, 2 = Base, 3 = Optimistic) | B5: 2
A6: Scenario selected | B6: =CHOOSE(B5,"Conservative","Base","Optimistic") -> Base
A7: Tax rate on EBIT | B7: 0.21
A8: D&A as % of sales | B8: 0.09
A9: Investment in NWC as % of change in sales | B9: 0.03
A10: Terminal growth rate (TGR) | B10: 0.03
A11: WACC | B11: =WACC!$B$21 -> 0.10852883
B13: Historical | C13: Historical | D13: Historical | E13: Projected | F13: Projected | G13: Projected | H13: Projected | I13: Projected
A14: Fiscal year ended 31 December | B14: 2023 | C14: 2024 | D14: 2025 | E14: 2026 | F14: 2027 | G14: 2028 | H14: 2029 | I14: 2030
A15: Revenue | B15: 574785 | C15: 637959 | D15: 716924 | E15: =D15*(1+E16) -> 795785.64 | F15: =E15*(1+F16) -> 875364.2 | G15: =F15*(1+G16) -> 954146.98 | H15: =G15*(1+H16) -> 1030478.7 | I15: =H15*(1+I16) -> 1102612.3
A16: % growth | C16: =C15/B15-1 -> 0.10990892 | D16: =D15/C15-1 -> 0.12377755 | E16: =CHOOSE($B$5,E17,E18,E19) -> 0.11 | F16: =CHOOSE($B$5,F17,F18,F19) -> 0.1 | G16: =CHOOSE($B$5,G17,G18,G19) -> 0.09 | H16: =CHOOSE($B$5,H17,H18,H19) -> 0.08 | I16: =CHOOSE($B$5,I17,I18,I19) -> 0.07
A17: Conservative scenario | E17: 0.09 | F17: 0.08 | G17: 0.07 | H17: 0.06 | I17: 0.05
A18: Base scenario | E18: 0.11 | F18: 0.1 | G18: 0.09 | H18: 0.08 | I18: 0.07
A19: Optimistic scenario | E19: 0.13 | F19: 0.12 | G19: 0.11 | H19: 0.1 | I19: 0.09
A20: EBIT (operating income) | B20: 36852 | C20: 68593 | D20: 79975 | E20: =E15*E21 -> 95494.277 | F20: =F15*F21 -> 109420.53 | G20: =G15*G21 -> 124039.11 | H20: =H15*H21 -> 139114.63 | I20: =I15*I21 -> 154365.72
A21: % of sales | B21: =B20/B15 -> 0.064114408 | C21: =C20/C15 -> 0.10751945 | D21: =D20/D15 -> 0.11155297 | E21: =CHOOSE($B$5,E22,E23,E24) -> 0.12 | F21: =CHOOSE($B$5,F22,F23,F24) -> 0.125 | G21: =CHOOSE($B$5,G22,G23,G24) -> 0.13 | H21: =CHOOSE($B$5,H22,H23,H24) -> 0.135 | I21: =CHOOSE($B$5,I22,I23,I24) -> 0.14
A22: Conservative scenario | E22: 0.11 | F22: 0.11 | G22: 0.115 | H22: 0.115 | I22: 0.12
A23: Base scenario | E23: 0.12 | F23: 0.125 | G23: 0.13 | H23: 0.135 | I23: 0.14
A24: Optimistic scenario | E24: 0.125 | F24: 0.135 | G24: 0.145 | H24: 0.155 | I24: 0.16
A25: Taxes | B25: 7120 | C25: 9265 | D25: 19087 | E25: =E20*$B$7 -> 20053.798 | F25: =F20*$B$7 -> 22978.31 | G25: =G20*$B$7 -> 26048.213 | H25: =H20*$B$7 -> 29214.072 | I25: =I20*$B$7 -> 32416.8
A26: % of EBIT | B26: =B25/B20 -> 0.19320525 | C26: =C25/C20 -> 0.13507209 | D26: =D25/D20 -> 0.23866208 | E26: =E25/E20 -> 0.21 | F26: =F25/F20 -> 0.21 | G26: =G25/G20 -> 0.21 | H26: =H25/H20 -> 0.21 | I26: =I25/I20 -> 0.21
A27: EBIAT (EBIT after taxes) | B27: =B20-B25 -> 29732 | C27: =C20-C25 -> 59328 | D27: =D20-D25 -> 60888 | E27: =E20-E25 -> 75440.479 | F27: =F20-F25 -> 86442.215 | G27: =G20-G25 -> 97990.895 | H27: =H20-H25 -> 109900.56 | I27: =I20-I25 -> 121948.92
A28: D&A | B28: 48663 | C28: 52795 | D28: 65756 | E28: =E15*$B$8 -> 71620.708 | F28: =F15*$B$8 -> 78782.778 | G28: =G15*$B$8 -> 85873.228 | H28: =H15*$B$8 -> 92743.087 | I28: =I15*$B$8 -> 99235.103
A29: % of sales | B29: =B28/B15 -> 0.084662961 | C29: =C28/C15 -> 0.082756102 | D29: =D28/D15 -> 0.091719624 | E29: =E28/E15 -> 0.09 | F29: =F28/F15 -> 0.09 | G29: =G28/G15 -> 0.09 | H29: =H28/H15 -> 0.09 | I29: =I28/I15 -> 0.09
A30: Capital expenditures | B30: 52729 | C30: 82999 | D30: 131819 | E30: =E15*E31 -> 135283.56 | F30: =F15*F31 -> 131304.63 | G30: =G15*G31 -> 124039.11 | H30: =H15*H31 -> 123657.45 | I30: =I15*I31 -> 121287.35
A31: % of sales | B31: =B30/B15 -> 0.09173691 | C31: =C30/C15 -> 0.13010084 | D31: =D30/D15 -> 0.18386747 | E31: 0.17 | F31: 0.15 | G31: 0.13 | H31: 0.12 | I31: 0.11
A32: Investment in net working capital | B32: -724 | C32: 1058 | D32: 4337 | E32: =(E15-D15)*$B$9 -> 2365.8492 | F32: =(F15-E15)*$B$9 -> 2387.3569 | G32: =(G15-F15)*$B$9 -> 2363.4834 | H32: =(H15-G15)*$B$9 -> 2289.9528 | I32: =(I15-H15)*$B$9 -> 2164.0054
A33: % of change in sales | C33: =C32/(C15-B15) -> 0.016747396 | D33: =D32/(D15-C15) -> 0.054923067 | E33: =$B$9 -> 0.03 | F33: =$B$9 -> 0.03 | G33: =$B$9 -> 0.03 | H33: =$B$9 -> 0.03 | I33: =$B$9 -> 0.03
A34: Unlevered free cash flow | B34: =B27+B28-B30-B32 -> 26390 | C34: =C27+C28-C30-C32 -> 28066 | D34: =D27+D28-D30-D32 -> -9512 | E34: =E27+E28-E30-E32 -> 9411.7783 | F34: =F27+F28-F30-F32 -> 31533.006 | G34: =G27+G28-G30-G32 -> 57461.532 | H34: =H27+H28-H30-H32 -> 76696.243 | I34: =I27+I28-I30-I32 -> 97732.665
A36: Discount period (years) | E36: 1 | F36: 2 | G36: 3 | H36: 4 | I36: 5
A37: Discount factor | E37: =1/(1+$B$11)^E36 -> 0.90209652 | F37: =1/(1+$B$11)^F36 -> 0.81377813 | G37: =1/(1+$B$11)^G36 -> 0.73410642 | H37: =1/(1+$B$11)^H36 -> 0.66223485 | I37: =1/(1+$B$11)^I36 -> 0.59739976
A38: Present value of free cash flow | E38: =E34*E37 -> 8490.3324 | F38: =F34*F37 -> 25660.871 | G38: =G34*G37 -> 42182.88 | H38: =H34*H37 -> 50790.925 | I38: =I34*I37 -> 58385.47
A40: Valuation
A41: Sum of present value of free cash flows | B41: =SUM(E38:I38) -> 185510.48
A42: Terminal value (Gordon growth) | B42: =I34*(1+B10)/(B11-B10) -> 1281881.4
A43: Present value of terminal value | B43: =B42*I37 -> 765795.64
A44: Enterprise value | B44: =B41+B43 -> 951306.12
...

Sheet WACC
A1: WACC: weighted average cost of capital
A2: Blue figures are inputs. USD millions unless stated.
A4: Cost of equity (CAPM)
A5: Risk-free rate | B5: 0.0418 | C5: 10-year US Treasury yield at 31 Dec 2025 (FRED, series DGS10)
A6: Beta | B6: 1.38 | C6: Own calculation: 60 monthly returns of Amazon against the S&P 500, Dec 2020 to Dec 2025 (Yahoo Finance)
A7: Equity risk premium | B7: 0.05 | C7: Assumption
A8: Cost of equity | B8: =B5+B6*B7 -> 0.1108 | C8: Risk-free rate + beta x equity risk premium
A9: Cost of debt
A10: Interest expense, 2025 | B10: 2274 | C10: Form 10-K
A11: Total debt, 31 Dec 2025 | B11: 68851 | C11: Form 10-K; excludes lease liabilities
A12: Pre-tax cost of debt | B12: =B10/B11 -> 0.033027843 | C12: Interest expense / total debt
A13: Tax rate | B13: =DCF!B7 -> 0.21 | C13: From the DCF assumptions
A14: After-tax cost of debt | B14: =B12*(1-B13) -> 0.026091996
A15: Capital structure
A16: Share price, 31 Dec 2025 (USD) | B16: 230.82001 | C16: Yahoo Finance closing price
A17: Diluted shares (millions) | B17: 10827 | C17: Form 10-K, weighted average for 2025
A18: Market value of equity | B18: =B16*B17 -> 2499088.2
A19: Equity weight | B19: =B18/(B18+B11) -> 0.97318823
A20: Debt weight | B20: =B11/(B18+B11) -> 0.026811772
A21: WACC | B21: =B19*B8+B20*B14 -> 0.10852883 | C21: Equity weight x cost of equity + debt weight x after-tax cost of debt

Sheet Sensitivity
A1: Sensitivity: value per share (USD) to WACC and terminal growth rate
A2: Uses the scenario selected on the DCF sheet. Rows: WACC. Columns: terminal growth rate.
A4: WACC \ TGR | B4: =DCF!$B$10+(-0.01) -> 0.02 | C4: =DCF!$B$10+(-0.005) -> 0.025 | D4: =DCF!$B$10+(0) -> 0.03 | E4: =DCF!$B$10+(0.005) -> 0.035 | F4: =DCF!$B$10+(0.01) -> 0.04
A5: =DCF!$B$11+(-0.01) -> 0.098528828 | B5: =(DCF!$E$34/(1+$A5)^1+DCF!$F$34/(1+$A5)^2+DCF!$G$34/(1+$A5)^3+DCF!$H$34/(1+$A5)^4+DCF!$I$34/(1+$A5)^5+DCF!$I$34*(1+B$4)/($A5-B$4)/(1+$A5)^5-DCF!$B$45+DCF!$B$46)/DCF!$B$48 -> 96.009114 | C5: =(DCF!$E$34/(1+$A5)^1+DCF!$F$34/(1+$A5)^2+DCF!$G$34/(1+$A5)^3+DCF!$H$34/(1+$A5)^4+DCF!$I$34/(1+$A5)^5+DCF!$I$34*(1+C$4)/($A5-C$4)/(1+$A5)^5-DCF!$B$45+DCF!$B$46)/DCF!$B$48 -> 101.37658 | D5: =(DCF!$E$34/(1+$A5)^1+DCF!$F$34/(1+$A5)^2+DCF!$G$34/(1+$A5)^3+DCF!$H$34/(1+$A5)^4+DCF!$I$34/(1+$A5)^5+DCF!$I$34*(1+D$4)/($A5-D$4)/(1+$A5)^5-DCF!$B$45+DCF!$B$46)/DCF!$B$48 -> 107.52728 | E5: =(DCF!$E$34/(1+$A5)^1+DCF!$F$34/(1+$A5)^2+DCF!$G$34/(1+$A5)^3+DCF!$H$34/(1+$A5)^4+DCF!$I$34/(1+$A5)^5+DCF!$I$34*(1+E$4)/($A5-E$4)/(1+$A5)^5-DCF!$B$45+DCF!$B$46)/DCF!$B$48 -> 114.64616 | F5: =(DCF!$E$34/(1+$A5)^1+DCF!$F$34/(1+$A5)^2+DCF!$G$34/(1+$A5)^3+DCF!$H$34/(1+$A5)^4+DCF!$I$34/(1+$A5)^5+DCF!$I$34*(1+F$4)/($A5-F$4)/(1+$A5)^5-DCF!$B$45+DCF!$B$46)/DCF!$B$48 -> 122.98134
A6: =DCF!$B$11+(-0.005) -> 0.10352883 | B6: =(DCF!$E$34/(1+$A6)^1+DCF!$F$34/(1+$A6)^2+DCF!$G$34/(1+$A6)^3+DCF!$H$34/(1+$A6)^4+DCF!$I$34/(1+$A6)^5+DCF!$I$34*(1+B$4)/($A6-B$4)/(1+$A6)^5-DCF!$B$45+DCF!$B$46)/DCF!$B$48 -> 89.781295 | C6: =(DCF!$E$34/(1+$A6)^1+DCF!$F$34/(1+$A6)^2+DCF!$G$34/(1+$A6)^3+DCF!$H$34/(1+$A6)^4+DCF!$I$34/(1+$A6)^5+DCF!$I$34*(1+C$4)/($A6-C$4)/(1+$A6)^5-DCF!$B$45+DCF!$B$46)/DCF!$B$48 -> 94.421118 | D6: =(DCF!$E$34/(1+$A6)^1+DCF!$F$34/(1+$A6)^2+DCF!$G$34/(1+$A6)^3+DCF!$H$34/(1+$A6)^4+DCF!$I$34/(1+$A6)^5+DCF!$I$34*(1+D$4)/($A6-D$4)/(1+$A6)^5-DCF!$B$45+DCF!$B$46)/DCF!$B$48 -> 99.691961 | E6: =(DCF!$E$34/(1+$A6)^1+DCF!$F$34/(1+$A6)^2+DCF!$G$34/(1+$A6)^3+DCF!$H$34/(1+$A6)^4+DCF!$I$34/(1+$A6)^5+DCF!$I$34*(1+E$4)/($A6-E$4)/(1+$A6)^5-DCF!$B$45+DCF!$B$46)/DCF!$B$48 -> 105.73195 | F6: =(DCF!$E$34/(1+$A6)^1+DCF!$F$34/(1+$A6)^2+DCF!$G$34/(1+$A6)^3+DCF!$H$34/(1+$A6)^4+DCF!$I$34/(1+$A6)^5+DCF!$I$34*(1+F$4)/($A6-F$4)/(1+$A6)^5-DCF!$B$45+DCF!$B$46)/DCF!$B$48 -> 112.72268
A7: =DCF!$B$11+(0) -> 0.10852883 | B7: =(DCF!$E$34/(1+$A7)^1+DCF!$F$34/(1+$A7)^2+DCF!$G$34/(1+$A7)^3+DCF!$H$34/(1+$A7)^4+DCF!$I$34/(1+$A7)^5+DCF!$I$34*(1+B$4)/($A7-B$4)/(1+$A7)^5-DCF!$B$45+DCF!$B$46)/DCF!$B$48 -> 84.26957 | C7: =(DCF!$E$34/(1+$A7)^1+DCF!$F$34/(1+$A7)^2+DCF!$G$34/(1+$A7)^3+DCF!$H$34/(1+$A7)^4+DCF!$I$34/(1+$A7)^5+DCF!$I$34*(1+C$4)/($A7-C$4)/(1+$A7)^5-DCF!$B$45+DCF!$B$46)/DCF!$B$48 -> 88.311535 | D7: =(DCF!$E$34/(1+$A7)^1+DCF!$F$34/(1+$A7)^2+DCF!$G$34/(1+$A7)^3+DCF!$H$34/(1+$A7)^4+DCF!$I$34/(1+$A7)^5+DCF!$I$34*(1+D$4)/($A7-D$4)/(1+$A7)^5-DCF!$B$45+DCF!$B$46)/DCF!$B$48 -> 92.868211 | E7: =(DCF!$E$34/(1+$A7)^1+DCF!$F$34/(1+$A7)^2+DCF!$G$34/(1+$A7)^3+DCF!$H$34/(1+$A7)^4+DCF!$I$34/(1+$A7)^5+DCF!$I$34*(1+E$4)/($A7-E$4)/(1+$A7)^5-DCF!$B$45+DCF!$B$46)/DCF!$B$48 -> 98.044599 | F7: =(DCF!$E$34/(1+$A7)^1+DCF!$F$34/(1+$A7)^2+DCF!$G$34/(1+$A7)^3+DCF!$H$34/(1+$A7)^4+DCF!$I$34/(1+$A7)^5+DCF!$I$34*(1+F$4)/($A7-F$4)/(1+$A7)^5-DCF!$B$45+DCF!$B$46)/DCF!$B$48 -> 103.97635
A8: =DCF!$B$11+(0.005) -> 0.11352883 | B8: =(DCF!$E$34/(1+$A8)^1+DCF!$F$34/(1+$A8)^2+DCF!$G$34/(1+$A8)^3+DCF!$H$34/(1+$A8)^4+DCF!$I$34/(1+$A8)^5+DCF!$I$34*(1+B$4)/($A8-B$4)/(1+$A8)^5-DCF!$B$45+DCF!$B$46)/DCF!$B$48 -> 79.35882 | C8: =(DCF!$E$34/(1+$A8)^1+DCF!$F$34/(1+$A8)^2+DCF!$G$34/(1+$A8)^3+DCF!$H$34/(1+$A8)^4+DCF!$I$34/(1+$A8)^5+DCF!$I$34*(1+C$4)/($A8-C$4)/(1+$A8)^5-DCF!$B$45+DCF!$B$46)/DCF!$B$48 -> 82.904222 | D8: =(DCF!$E$34/(1+$A8)^1+DCF!$F$34/(1+$A8)^2+DCF!$G$34/(1+$A8)^3+DCF!$H$34/(1+$A8)^4+DCF!$I$34/(1+$A8)^5+DCF!$I$34*(1+D$4)/($A8-D$4)/(1+$A8)^5-DCF!$B$45+DCF!$B$46)/DCF!$B$48 -> 86.874077 | E8: =(DCF!$E$34/(1+$A8)^1+DCF!$F$34/(1+$A8)^2+DCF!$G$34/(1+$A8)^3+DCF!$H$34/(1+$A8)^4+DCF!$I$34/(1+$A8)^5+DCF!$I$34*(1+E$4)/($A8-E$4)/(1+$A8)^5-DCF!$B$45+DCF!$B$46)/DCF!$B$48 -> 91.349461 | F8: =(DCF!$E$34/(1+$A8)^1+DCF!$F$34/(1+$A8)^2+DCF!$G$34/(1+$A8)^3+DCF!$H$34/(1+$A8)^4+DCF!$I$34/(1+$A8)^5+DCF!$I$34*(1+F$4)/($A8-F$4)/(1+$A8)^5-DCF!$B$45+DCF!$B$46)/DCF!$B$48 -> 96.433501
A9: =DCF!$B$11+(0.01) -> 0.11852883 | B9: =(DCF!$E$34/(1+$A9)^1+DCF!$F$34/(1+$A9)^2+DCF!$G$34/(1+$A9)^3+DCF!$H$34/(1+$A9)^4+DCF!$I$34/(1+$A9)^5+DCF!$I$34*(1+B$4)/($A9-B$4)/(1+$A9)^5-DCF!$B$45+DCF!$B$46)/DCF!$B$48 -> 74.957302 | C9: =(DCF!$E$34/(1+$A9)^1+DCF!$F$34/(1+$A9)^2+DCF!$G$34/(1+$A9)^3+DCF!$H$34/(1+$A9)^4+DCF!$I$34/(1+$A9)^5+DCF!$I$34*(1+C$4)/($A9-C$4)/(1+$A9)^5-DCF!$B$45+DCF!$B$46)/DCF!$B$48 -> 78.086291 | D9: =(DCF!$E$34/(1+$A9)^1+DCF!$F$34/(1+$A9)^2+DCF!$G$34/(1+$A9)^3+DCF!$H$34/(1+$A9)^4+DCF!$I$34/(1+$A9)^5+DCF!$I$34*(1+D$4)/($A9-D$4)/(1+$A9)^5-DCF!$B$45+DCF!$B$46)/DCF!$B$48 -> 81.568723 | E9: =(DCF!$E$34/(1+$A9)^1+DCF!$F$34/(1+$A9)^2+DCF!$G$34/(1+$A9)^3+DCF!$H$34/(1+$A9)^4+DCF!$I$34/(1+$A9)^5+DCF!$I$34*(1+E$4)/($A9-E$4)/(1+$A9)^5-DCF!$B$45+DCF!$B$46)/DCF!$B$48 -> 85.468069 | F9: =(DCF!$E$34/(1+$A9)^1+DCF!$F$34/(1+$A9)^2+DCF!$G$34/(1+$A9)^3+DCF!$H$34/(1+$A9)^4+DCF!$I$34/(1+$A9)^5+DCF!$I$34*(1+F$4)/($A9-F$4)/(1+$A9)^5-DCF!$B$45+DCF!$B$46)/DCF!$B$48 -> 89.863965
A11: Market price, 31 Dec 2025 (USD) | B11: =WACC!B16 -> 230.82001

Sheet Scenarios
A1: Scenario results
A2: Values recorded from the DCF sheet with the scenario switch set to 1, 2 and 3. Record them again if any input changes.
A4: Scenario | B4: Revenue 2030 | C4: EBIT margin 2030 | D4: Free cash flow 2030 | E4: Enterprise value | F4: Equity value | G4: Value per share (USD) | H4: Against market price
A5: Conservative | B5: 1005083.9 | C5: 0.12 | D5: 73744.441 | E5: 711860.16 | F5: 766038.16 | G5: 70.752578 | H5: -0.69347294
A6: Base | B6: 1102612.3 | C6: 0.14 | D6: 97732.665 | E6: 951306.12 | F6: 1005484.1 | G6: 92.868211 | H6: -0.59765962
A7: Optimistic | B7: 1207568.4 | C7: 0.16 | D7: 125494.06 | E7: 1220292.5 | F7: 1274470.5 | G7: 117.71225 | H7: -0.49002579

Sheet Notes
A1: Notes
A2: Method
A3: Unlevered free cash flow = EBIT after taxes + D&A - capital expenditures - investment in net working capital.
A4: Free cash flows for 2026 to 2030 and the terminal value are discounted at the WACC to 31 December 2025, using end-of-year discounting.
A5: Terminal value = free cash flow of 2030 x (1 + terminal growth rate) / (WACC - terminal growth rate).
A6: Equity value = enterprise value - total debt + cash and short-term investments.
A8: Assumptions
A9: Revenue growth, EBIT margin and capital expenditures for 2026 to 2030 are the author's assumptions, not company guidance or analyst forecasts. Change the blue cells to test other views.
A10: The equity risk premium of 5.0% and the terminal growth rate of 3.0% are assumptions.
A11: Stock-based compensation is not added back: EBIT is taken after that expense.
A12: Historical investment in net working capital is the sum of the working capital lines of the cash flow statement (inventories, receivables, payables, accrued expenses, unearned revenue).
A13: Total debt excludes lease liabilities. Diluted shares are the weighted average for 2025.
... A19: Retrieved on 2026-10-13.
